<?xml version="1.0" ?>
<!-- =================================================================================== -->
<!-- |    This document was autogenerated by xacro from ./urdf.xacro                   | -->
<!-- |    EDITING THIS FILE BY HAND IS NOT RECOMMENDED                                 | -->
<!-- =================================================================================== -->
<robot name="sawyer_no_base" xmlns:xacro="http://www.ros.org/wiki/xacro">
  <material name="black">
    <color rgba="0 0 0 1"/>
  </material>
  <material name="darkgray">
    <color rgba=".2 .2 .2 1"/>
  </material>
  <material name="darkred">
    <color rgba=".5 .1 .1 1"/>
  </material>
  <material name="sawyer_red">
    <color rgba=".5 .1 .1 1"/>
  </material>
  <material name="sawyer_gray">
    <color rgba="0.75294 0.75294 0.75294 1"/>
  </material>

  <link name="right_arm_base_link">
    <inertial>
      <origin rpy="0 0 0" xyz="-0.0006241 -2.8025E-05 0.065404"/>
      <mass value="2.0687"/>
      <inertia ixx="0.0067599" ixy="0" ixz="0" iyy="0.0067877" iyz="0" izz="0.0074031"/>
    </inertial>
    <visual>
      <origin rpy="0 0 0" xyz="0 0 0"/>
      <geometry>
        <mesh filename="package://sawyer_description/meshes/sawyer_pv/base.DAE"/>
      </geometry>
      <material name="sawyer_red"/>
    </visual>
    <collision>
      <origin rpy="0 0 0" xyz="0 0 0.12"/>
      <geometry>
        <cylinder length="0.24" radius="0.08"/>
      </geometry>
    </collision>
  </link>
  <link name="right_l0">
    <inertial>
      <origin rpy="0 0 0" xyz="0.024366 0.010969 0.14363"/>
      <mass value="5.3213"/>
      <inertia ixx="0.053314" ixy="0" ixz="0" iyy="0.057902" iyz="0" izz="0.023659"/>
    </inertial>
    <visual>
      <origin rpy="0 0 0" xyz="0 0 0"/>
      <geometry>
        <mesh filename="package://sawyer_description/meshes/sawyer_mp3/l0.DAE"/>
      </geometry>
      <material name="sawyer_red"/>
    </visual>
    <collision>
      <origin rpy="0 0 0" xyz="0.081 0 0.237"/>
      <geometry>
        <sphere radius="0.07"/>
      </geometry>
    </collision>
  </link>
  <joint name="right_j0" type="revolute">
    <origin rpy="0 0 0" xyz="0 0 0.08"/>
    <parent link="right_arm_base_link"/>
    <child link="right_l0"/>
    <axis xyz="0 0 1"/>
    <limit effort="80.0" lower="-3.0503" upper="3.0503" velocity="1.74"/>
  </joint>

  <link name="right_l1">
    <inertial>
      <origin rpy="0 0 0" xyz="-0.0030849 -0.026811 0.092521"/>
      <mass value="4.505"/>
      <inertia ixx="0.022398" ixy="0" ixz="0" iyy="0.014613" iyz="0" izz="0.017295"/>
    </inertial>
    <visual>
      <origin rpy="0 0 0" xyz="0 0 0"/>
      <geometry>
        <mesh filename="package://sawyer_description/meshes/sawyer_mp3/l1.DAE"/>
      </geometry>
      <material name="sawyer_red"/>
    </visual>
    <collision>
      <origin rpy="0 0 0" xyz="0 0 0.1225"/>
      <geometry>
        <sphere radius="0.07"/>
      </geometry>
    </collision>
  </link>
  <joint name="right_j1" type="revolute">
    <origin rpy="-1.57079632679 1.57079632679 0" xyz="0.081 0.05 0.237"/>
    <parent link="right_l0"/>
    <child link="right_l1"/>
    <axis xyz="0 0 1"/>
    <limit effort="80.0" lower="-3.8183" upper="2.2824" velocity="1.328"/>
  </joint>
  <link name="right_l2">
    <inertial>
      <origin rpy="0 0 0" xyz="-0.00016044 -0.014967 0.13582"/>
      <mass value="1.745"/>
      <inertia ixx="0.025506" ixy="0" ixz="0" iyy="0.0253" iyz="0" izz="0.0034179"/>
    </inertial>
    <visual>
      <origin rpy="0 0 0" xyz="0 0 0"/>
      <geometry>
        <mesh filename="package://sawyer_description/meshes/sawyer_pv/l2.DAE"/>
      </geometry>
      <material name="sawyer_red"/>
    </visual>
    <collision>
      <origin rpy="0 0 0" xyz="0 0 0.14"/>
      <geometry>
        <cylinder length="0.35" radius="0.06"/>
      </geometry>
    </collision>
  </link>
  <joint name="right_j2" type="revolute">
    <origin rpy="1.57079632679 0 0" xyz="0 -0.14 0.1425"/>
    <parent link="right_l1"/>
    <child link="right_l2"/>
    <axis xyz="0 0 1"/>
    <limit effort="40.0" lower="-3.0514" upper="3.0514" velocity="1.957"/>
  </joint>
  <link name="right_l3">
    <inertial>
      <origin rpy="0 0 0" xyz="-0.0048135 -0.0281 -0.084154"/>
      <mass value="2.5097"/>
      <inertia ixx="0.01016" ixy="0" ixz="0" iyy="0.0065685" iyz="0" izz="0.0069078"/>
    </inertial>
    <visual>
      <origin rpy="0 0 0" xyz="0 0 0"/>
      <geometry>
        <mesh filename="package://sawyer_description/meshes/sawyer_pv/l3.DAE"/>
      </geometry>
      <material name="sawyer_red"/>
    </visual>
    <collision>
      <origin rpy="0 0 0" xyz="0 -0.01 -0.12"/>
      <geometry>
        <sphere radius="0.06"/>
      </geometry>
    </collision>
  </link>
  <joint name="right_j3" type="revolute">
    <origin rpy="-1.57079632679 0 0" xyz="0 -0.042 0.26"/>
    <parent link="right_l2"/>
    <child link="right_l3"/>
    <axis xyz="0 0 1"/>
    <limit effort="40.0" lower="-3.0514" upper="3.0514" velocity="1.957"/>
  </joint>
  <link name="right_l4">
    <inertial>
      <origin rpy="0 0 0" xyz="-0.0018844 0.0069001 0.1341"/>
      <mass value="1.1136"/>
      <inertia ixx="0.013557" ixy="0" ixz="0" iyy="0.013555" iyz="0" izz="0.0013658"/>
    </inertial>
    <visual>
      <origin rpy="0 0 0" xyz="0 0 0"/>
      <geometry>
        <mesh filename="package://sawyer_description/meshes/sawyer_pv/l4.DAE"/>
      </geometry>
      <material name="sawyer_red"/>
    </visual>
    <collision>
      <origin rpy="0 0 0" xyz="0 0 0.14"/>
      <geometry>
        <cylinder length="0.36" radius="0.045"/>
      </geometry>
    </collision>
  </link>
  <joint name="right_j4" type="revolute">
    <origin rpy="1.57079632679 0 0" xyz="0 -0.125 -0.1265"/>
    <parent link="right_l3"/>
    <child link="right_l4"/>
    <axis xyz="0 0 1"/>
    <limit effort="9.0" lower="-2.9842" upper="2.9842" velocity="3.485"/>
  </joint>

  <link name="right_l5">
    <inertial>
      <origin rpy="0 0 0" xyz="0.0061133 -0.023697 0.076416"/>
      <mass value="1.5625"/>
      <inertia ixx="0.0047328" ixy="0" ixz="0" iyy="0.0029676" iyz="0" izz="0.0031762"/>
    </inertial>
    <visual>
      <origin rpy="0 0 0" xyz="0 0 0"/>
      <geometry>
        <mesh filename="package://sawyer_description/meshes/sawyer_pv/l5.STL"/>
      </geometry>
      <material name="sawyer_red"/>
    </visual>
    <collision>
      <origin rpy="0 0 0" xyz="0.01 0 0.09"/>
      <geometry>
        <sphere radius="0.06"/>
      </geometry>
    </collision>
  </link>
  <joint name="right_j5" type="revolute">
    <origin rpy="-1.57079632679 0 0" xyz="0 0.031 0.275"/>
    <parent link="right_l4"/>
    <child link="right_l5"/>
    <axis xyz="0 0 1"/>
    <limit effort="9.0" lower="-2.9842" upper="2.9842" velocity="3.485"/>
  </joint>
  <link name="right_l6">
    <inertial>
      <origin rpy="0 0 0" xyz="-8.0726E-06 0.0085838 -0.0049566"/>
      <mass value="0.3292"/>
      <inertia ixx="0.00031105" ixy="0" ixz="0" iyy="0.00021549" iyz="0" izz="0.00035976"/>
    </inertial>
    <visual>
      <origin rpy="0 0 0" xyz="0 0 0"/>
      <geometry>
        <mesh filename="package://sawyer_description/meshes/sawyer_mp1/l6.STL"/>
      </geometry>
      <material name="darkgray"/>
    </visual>
    <collision>
      <origin rpy="0 0 0" xyz="0 0 -0.005"/>
      <geometry>
        <cylinder length="0.05" radius="0.065"/>
      </geometry>
    </collision>
  </link>
  <joint name="right_j6" type="revolute">
    <origin rpy="-1.57079632679 -0.17453 3.1416" xyz="0 -0.11 0.1053"/>
    <parent link="right_l5"/>
    <child link="right_l6"/>
    <axis xyz="0 0 1"/>
    <limit effort="9.0" lower="-4.7104" upper="4.7104" velocity="4.545"/>
  </joint>
  <link name="right_hand">
    <collision>
      <origin rpy="0 0 0" xyz="0 0 0"/>
      <geometry>
        <cylinder length="0" radius="0"/>
      </geometry>
    </collision>
    <inertial>
      <origin rpy="0 0 0" xyz="1e-08 1e-08 1e-08"/>
      <mass value="1e-08"/>
      <inertia ixx="1e-08" ixy="1e-08" ixz="1e-08" iyy="1e-08" iyz="1e-08" izz="1e-08"/>
    </inertial>
  </link>
  <joint name="right_hand" type="fixed">
    <origin rpy="0 0 1.5708" xyz="0 0 0.0245"/>
    <axis xyz="0 0 1"/>
    <parent link="right_l6"/>
    <child link="right_hand"/>
  </joint>

  <!-- Base of end effector -->
  <link name="right_gripper_base">
    <visual>
      <origin rpy="0 0 0" xyz="0 0 0"/>
      <geometry>
        <mesh filename="package://rethink_ee_description/meshes/electric_gripper/electric_gripper_base.STL"/>
      </geometry>
      <material name="sawyer_red"/>
    </visual>
    <collision>
      <origin rpy="-1.57079632679 3.14159265359 0" xyz="0.0 0.0 0"/>
      <geometry>
        <cylinder length="0.1" radius="0.029"/>
      </geometry>
      <material name="darkgray"/>
    </collision>
    <inertial>
      <inertia ixx="1.0e-01" ixy=".01" ixz=".01" iyy="1.0e-01" iyz=".01" izz="1.0e-01"/>
      <mass value="0.47"/>
      <origin rpy="-1.57079632679 3.14159265359 0" xyz="0.0028 -0.0004 0.0343"/>
    </inertial>
  </link>
  <link name="r_gripper_l_finger">
    <visual>
      <origin rpy="0 0 -3.14159265359" xyz="0 0 0"/>
      <geometry>
        <mesh filename="package://rethink_ee_description/meshes/electric_gripper/fingers/standard_narrow.STL"/>
      </geometry>
      <material name="darkgray"/>
    </visual>
    <collision>
      <origin rpy="0 0 -3.14159265359" xyz="0 0.01725 0.04"/>
      <geometry>
        <box size="0.01 0.0135 0.075"/>
      </geometry>
    </collision>
    <collision>
      <origin rpy="0 0 -3.14159265359" xyz="-0.005 -0.003 0.0083"/>
      <geometry>
        <box size="0.01 0.05 0.017"/>
      </geometry>
    </collision>
    <inertial>
      <inertia ixx="1.1e-09" ixy="0" ixz="0" iyy="1.1e-09" iyz="0" izz="1.1e-09"/>
      <mass value="2.0e-06"/>
      <origin rpy="0 0 0" xyz="0 0 0"/>
    </inertial>
  </link>
  <gazebo reference="r_gripper_l_finger">
    <mu1>1000</mu1>
    <mu2>1000</mu2>
    <fdir1>0.0 0.0 1.0</fdir1>
    <kp>1e5</kp>
    <kd>1.0</kd>
  </gazebo>
  <link name="r_gripper_l_finger_tip">
    <contact>
      <lateral_friction value="100"/>
      <spinning_friction value="10"/>
      <rolling_friction value="10"/>
    </contact>
    <visual>
      <origin rpy="0 0 3.14159265359" xyz="0 0 0"/>
      <geometry>
        <mesh filename="package://rethink_ee_description/meshes/electric_gripper/fingers/basic_soft_tip.STL"/>
      </geometry>
      <material name="darkgray"/>
    </visual>
    <collision>
      <origin rpy="0 0 3.14159265359" xyz="0 -0.0045 -0.015"/>
      <geometry>
        <box size="0.015 0.006 0.037"/>
      </geometry>
    </collision>
    <inertial>
      <inertia ixx="1.10e-09" ixy="0" ixz="0" iyy="1.1e-09" iyz="0" izz="1.10e-09"/>
      <mass value="0.00001"/>
      <origin rpy="0 0 0" xyz="0 0 0"/>
    </inertial>
  </link>
  <joint name="r_gripper_l_finger_tip_joint" type="fixed">
    <origin rpy="0 0 0" xyz="0.0 0.01725 0.075"/>
    <parent link="r_gripper_l_finger"/>
    <child link="r_gripper_l_finger_tip"/>
  </joint>
  <link name="r_gripper_r_finger">
    <visual>
      <origin rpy="0 0 -0.0" xyz="0 0 0"/>
      <geometry>
        <mesh filename="package://rethink_ee_description/meshes/electric_gripper/fingers/standard_narrow.STL"/>
      </geometry>
      <material name="darkgray"/>
    </visual>
    <collision>
      <origin rpy="0 0 -0.0" xyz="0 -0.01725 0.04"/>
      <geometry>
        <box size="0.01 0.0135 0.075"/>
      </geometry>
    </collision>
    <collision>
      <origin rpy="0 0 -0.0" xyz="0.005 0.003 0.0083"/>
      <geometry>
        <box size="0.01 0.05 0.017"/>
      </geometry>
    </collision>
    <inertial>
      <origin rpy="0 0 -0.0" xyz="0 0 0"/>
      <mass value="0.02"/>
      <inertia ixx="0.01" ixy="0" ixz="0" iyy="0.01" iyz="0" izz="0.01"/>
    </inertial>
  </link>
  <gazebo reference="r_gripper_r_finger">
    <mu1>1000</mu1>
    <mu2>1000</mu2>
    <fdir1>0.0 0.0 1.0</fdir1>
    <kp>1e5</kp>
    <kd>1.0</kd>
  </gazebo>
  <link name="r_gripper_r_finger_tip">
    <contact>
      <lateral_friction value="100"/>
      <spinning_friction value="10"/>
      <rolling_friction value="10"/>
    </contact>
    <visual>
      <origin rpy="0 0 0.0" xyz="0 0 0"/>
      <geometry>
        <mesh filename="package://rethink_ee_description/meshes/electric_gripper/fingers/basic_soft_tip.STL"/>
      </geometry>
      <material name="darkgray"/>
    </visual>
    <collision>
      <origin rpy="0 0 0.0" xyz="0 0.0045 -0.015"/>
      <geometry>
        <box size="0.015 0.006 0.037"/>
      </geometry>
    </collision>
    <inertial>
      <inertia ixx="1.10e-09" ixy="0" ixz="0" iyy="1.1e-09" iyz="0" izz="1.10e-09"/>
      <mass value="0.00001"/>
      <origin rpy="0 0 0" xyz="0 0 0"/>
    </inertial>
  </link>
  <joint name="r_gripper_r_finger_tip_joint" type="fixed">
    <origin rpy="0 0 0" xyz="0.0 -0.01725 0.075"/>
    <parent link="r_gripper_r_finger"/>
    <child link="r_gripper_r_finger_tip"/>
  </joint>
  <!-- Electric PrismaticGripper Base Joint -->
   <joint name="right_gripper_base" type="fixed">
    <origin rpy="0 0 0" xyz="0 0 0.025"/>
    <parent link="right_hand"/>
    <child link="right_gripper_base"/>
  </joint>
  <!-- Electric PrismaticGripper Tip joint -->
  <joint name="right_endpoint" type="fixed">
    <origin rpy="0 0 0" xyz="0 0 0.095"/>
    <parent link="right_gripper_base"/>
    <child link="right_gripper"/>
  </joint>
  <!-- Electric PrismaticGripper Tip link -->
  <link name="right_gripper">
    <inertial>
      <origin rpy="0 0 0" xyz="0 0 0"/>
      <mass value="0.0001"/>
      <inertia ixx="0" ixy="0" ixz="0" iyy="0" iyz="0" izz="0.0"/>
    </inertial>
  </link>
  <joint name="r_gripper_l_finger_joint" type="prismatic">
    <origin rpy="0 0 0" xyz="0.0 -0.0015 0.02"/>
    <axis xyz="0 1 0"/>
    <parent link="right_gripper_base"/>
    <child link="r_gripper_l_finger"/>
    <limit effort="20.0" lower="0.0" upper="0.020833" velocity="5.0"/>
    <dynamics damping="0.7" friction="0.0"/>
  </joint>
  <joint name="r_gripper_r_finger_joint" type="prismatic">
    <origin rpy="0 0 0" xyz="0.0 0.0015 0.02"/>
    <axis xyz="0 1 0"/>
    <parent link="right_gripper_base"/>
    <child link="r_gripper_r_finger"/>
    <limit effort="20.0" lower="-0.020833" upper="0.0" velocity="5.0"/>
    <mimic joint="r_gripper_l_finger_joint" multiplier="-1.0"/>
    <dynamics damping="0.7" friction="0.0"/>
  </joint>
  <transmission name="gripper_right1">
    <type>transmission_interface/SimpleTransmission</type>
    <joint name="r_gripper_r_finger_joint">
      <hardwareInterface>EffortJointInterface</hardwareInterface>
    </joint>
    <actuator name="gripper_r1_motor1">
      <hardwareInterface>EffortJointInterface</hardwareInterface>
      <mechanicalReduction>1</mechanicalReduction>
    </actuator>
  </transmission>
  <transmission name="gripper_right2">
    <type>transmission_interface/SimpleTransmission</type>
    <joint name="r_gripper_l_finger_joint">
      <hardwareInterface>EffortJointInterface</hardwareInterface>
    </joint>
    <actuator name="gripper_r1_motor2">
      <hardwareInterface>EffortJointInterface</hardwareInterface>
      <mechanicalReduction>1</mechanicalReduction>
    </actuator>
  </transmission>
  <gazebo reference="r_gripper_r_finger_joint">
    <implicitSpringDamper>1</implicitSpringDamper>
  </gazebo>
  <gazebo reference="r_gripper_l_finger_joint">
    <implicitSpringDamper>1</implicitSpringDamper>
  </gazebo>
</robot>
