<?xml version="1.0"?>
<robot name="ikea">
  <link name ="rb0">
    <visual>
      <origin xyz='0.022180 0.552208 0.418122' rpy='0.022296 -1.404355 -0.002711'/>
      <geometry>
        <mesh filename="package://articulated_objects_db/data/objects/ikea/meshes/ikea_base.dae"  scale="1 1 1" />
      </geometry>
    </visual>
  </link>
  <joint name="j_0_1" type="prismatic">
    <parent link="rb0"/>
    <child link="rb1"/>
    <origin xyz="0.217860996453 -0.0578551077004 0.473953682013" rpy="0 0 0 "/>
    <axis xyz="0.993345970953 0.00472787271649 -0.115071409178"/>
    <limit effort="30" velocity="1.0" lower="-3.1416" upper="3.1416"/>
  </joint>
  <joint name="j_0_fixed" type="fixed">
    <parent link="rb1"/>
    <child link="rb1_marker"/>
      <origin xyz="0.0 0.0 0.0" rpy="1.67516747114 -0.047479998167 1.60579785099"/>
    <limit effort="30" velocity="1.0" lower="-3.1416" upper="3.1416"/>
  </joint>
  <joint name="j_0_2" type="revolute">
    <parent link="rb0"/>
    <child link="rb2"/>
    <origin xyz="0.18966307383 0.0549552994237 0.367074366162" rpy="0 0 0 "/>
    <axis xyz="-0.0373269377607 0.999291610171 -0.00479349127949"/>
    <limit effort="30" velocity="1.0" lower="-3.1416" upper="3.1416"/>
  </joint>
  <joint name="j_1_fixed" type="fixed">
    <parent link="rb2"/>
    <child link="rb2_marker"/>
      <origin xyz="0.0111909507171 -0.00123738202531 -0.295118883249" rpy="2.97920365551 -0.859284197544 -0.227513165653"/>
    <limit effort="30" velocity="1.0" lower="-3.1416" upper="3.1416"/>
  </joint>
  <link name ="rb1">
  </link>
  <link name ="rb1_marker">
    <visual>
      <origin xyz='-0.050028 0.105969 -0.165504' rpy='3.076699 -1.528233 3.141591'/>
      <geometry>
        <mesh filename="package://articulated_objects_db/data/objects/ikea/meshes/ikea_drawer.dae"  scale="1 1 1" />
      </geometry>
    </visual>
  </link>
  <link name ="rb2">
  </link>
  <link name ="rb2_marker">
    <visual>
      <origin xyz='0.312712 0.176150 -0.208321' rpy='-0.988543 -0.912821 -0.669597'/>
      <geometry>
        <mesh filename="package://articulated_objects_db/data/objects/ikea/meshes/ikea_door.dae"  scale="1 1 1" />
      </geometry>
    </visual>
  </link>
</robot>
